I'm sorry, but an uncaught exception occurred.

While running game code:
  File "game/script.rpy", line 128, in script
    chel1 "Паршивец мелкий!"
Exception: Sayer 'chel1' is not defined.

-- Full Traceback ------------------------------------------------------------

Full traceback:
  File "game/script.rpy", line 128, in script
    chel1 "Паршивец мелкий!"
  File "C:\Users\yarov\Downloads\renpy-8.2.0-sdk\renpy\ast.py", line 2557, in execute
    Say.execute(self)
  File "C:\Users\yarov\Downloads\renpy-8.2.0-sdk\renpy\ast.py", line 575, in execute
    who = eval_who(self.who, self.who_fast)
  File "C:\Users\yarov\Downloads\renpy-8.2.0-sdk\renpy\ast.py", line 464, in eval_who
    raise Exception("Sayer '%s' is not defined." % who)
Exception: Sayer 'chel1' is not defined.

Windows-10-10.0.22631 AMD64
Ren'Py 8.2.0.24012702
A plague of the shadow 1.0
Thu Feb 29 23:49:49 2024
